Workbook

Sheet 00_Resumen
A1: BASE MAESTRA AGRO v1.1 — INTEGRADA · EPN TARGET · AUDITADA
A3: Campo | B3: Valor | C3: Interpretación | E3: Elegibilidad/estrato | F3: N | G3: Cobertura disponible | H3: Datasets
A4: Estado | B4: NORMALIZADA_AUDITADA_CONGELADA | C4: Cierre v1.0 aprobado con observaciones documentadas; no modificar silenciosamente. | E4: Grado/Bachelor | F4: =COUNTIF('01_Datasets_Origen'!J:J,"Grado/Bachelor") -> 18 | G4: Con algún contenido | H4: =COUNTIF('01_Datasets_Origen'!N2:N25,"Sí")+COUNTIF('01_Datasets_Origen'!N2:N25,"Condicional") -> 4
A5: Metodología | B5: Plantilla Maestra v1.1 + Extractor v1.1 + Auditor v1.0 + Capa Analítica Formativa | C5: Extracción y normalización siguen separadas. | E5: Ingénieur/Master | F5: =COUNTIF('01_Datasets_Origen'!J:J,"Ingénieur/Master") -> 7 | G5: Con alguna carga | H5: =COUNTIF('01_Datasets_Origen'!O2:O25,"Sí")+COUNTIF('01_Datasets_Origen'!O2:O25,"Condicional") -> 13
A6: Datasets de origen | B6: =COUNTA('01_Datasets_Origen'!A2:A100) -> 25 | C6: Archivos institucionales preservados. | E6: Elegible créditos | F6: =COUNTIF('01_Datasets_Origen'!M:M,"Sí") -> 17 | G6: Con formativa de asignatura | H6: =COUNTIF('01_Datasets_Origen'!P2:P25,"Sí")+COUNTIF('01_Datasets_Origen'!P2:P25,"Condicional") -> 7
A7: Currículos únicos | B7: =COUNTA('03_Curriculos'!A2:A100) -> 23 | C7: IPB–IPLeiria–IPVC cuentan como un currículo conjunto. | E7: Créditos condicionales | F7: =COUNTIF('01_Datasets_Origen'!M:M,"Condicional") -> 1 | G7: Con crédito utilizable | H7: =COUNTIF('01_Datasets_Origen'!M2:M25,"Sí")+COUNTIF('01_Datasets_Origen'!M2:M25,"Condicional") -> 17
A8: Instituciones | B8: =COUNTA('02_Universidades'!A2:A100) -> 25 | C8: Instituciones asociadas a currículos. | E8: No elegible créditos | F8: =COUNTIF('01_Datasets_Origen'!M:M,"No") -> 7
A9: Relaciones currículo–institución | B9: =COUNTA('04_Curriculo_Institucion'!A2:A100) -> 25 | C9: Permite títulos conjuntos sin duplicar mallas. | E9: Elegible contenidos | F9: =COUNTIF('01_Datasets_Origen'!N:N,"Sí") -> 0
A10: Asignaturas canónicas | B10: =COUNTA('09_Asignaturas'!A2:A2000) -> 753 | C10: Filas integradas en staging. | E10: Elegible carga | F10: =COUNTIF('01_Datasets_Origen'!O:O,"Sí") -> 6
A11: Registros de carga | B11: =COUNTA('10_Carga_Academica'!A2:A2000) -> 418 | C11: Solo carga explícitamente publicada. | E11: Elegible formativa asignatura | F11: =COUNTIF('01_Datasets_Origen'!P:P,"Sí") -> 0
A12: Registros de contenidos | B12: =COUNTA('11_Contenidos'!A2:A2000) -> 93 | C12: Cobertura temática explícita.
A13: Resultados | B13: =COUNTA('12_Resultados'!A2:A2000) -> 167 | C13: Resultados/competencias documentados. | E13: Nivel comparativo | F13: N
A14: Evidencias | B14: =COUNTA('17_Evidencias'!A2:A3000) -> 1012 | C14: Trazabilidad documental. | E14: Grado/Bachelor | F14: =COUNTIF('01_Datasets_Origen'!J:J,"Grado/Bachelor") -> 18
A15: Formativa programa | B15: =COUNTA('22_Formativa_Programa'!A2:A2000) -> 171 | C15: Objetivos/perfiles/competencias de programa. | E15: Ingénieur/Master | F15: =COUNTIF('01_Datasets_Origen'!J:J,"Ingénieur/Master") -> 7
A16: Formativa asignatura | B16: =COUNTA('23_Formativa_Asignatura'!A2:A2000) -> 753 | C16: Usar bandera de elegibilidad para distinguir datos reales de NR.
A17: Mapeos formativos | B17: =COUNTA('24_Mapeo_Formativo'!A2:A2000) -> 174 | C17: Relaciones formativas documentadas.
A18: USC asignaturas integradas | B18: =COUNTIF('09_Asignaturas'!A:A,"CUR_AGRO_USC") -> 0 | C18: Debe permanecer en 0.
A19: Asignaturas currículo conjunto PT | B19: =COUNTIF('09_Asignaturas'!A:A,"CUR_AGRO_PT_EA_JOINT_IPB_IPL_IPVC") -> 30 | C19: Una sola malla conjunta.
A20: Normalización temática | B20: COMPLETADA — AGRO-NORM-v1.0 CONGELADO | C20: 676 asignaturas APROBADO; 17 REVISAR preservadas como gaps no bloqueantes.
A33: NORMALIZACIÓN AGRO v1.0 | B33: Resultado | C33: Interpretación
A34: Estado | B34: NORMALIZADA_AUDITADA_CON_OBSERVACIONES | C34: Normalización ejecutada y auditada sobre las 693 asignaturas.
A35: Normalizador | B35: AGRO-NORM-v1.0 | C35: Taxonomía congelada durante la corrida.
A36: Asignaturas APROBADO | B36: 676 | C36: 97,5% de las asignaturas.
A37: Asignaturas REVISAR | B37: 17 | C37: Se conservan sin familia forzada; documentadas como gaps.
A38: Familias usadas | B38: 99 | C38: De 111 familias disponibles.
A39: Áreas representadas | B39: 17 | C39: A00–A16.
A40: Capa formativa programa | B40: 158 registros | C40: 138 normalizados; 20 categorías contextuales quedan REVISAR.
A41: Capa formativa asignatura | B41: 693 registros | C41: No se derivan objetivos/RA/competencias ausentes.
A42: Hallazgos estructurales | B42: 8 | C42: Candidatos para AGRO-NORM-v1.1; v1.0 permanece congelada.
A43: Siguiente fase | B43: Benchmark/rediseño EPN sobre base congelada | C43: Cambios estructurales o taxonómicos requieren versión v1.1 explícita.
A44: Dictamen | B44: APROBADO CON OBSERVACIONES DOCUMENTADAS — CONGELADO | C44: Apta para benchmarking normalizado. Aplicar banderas de elegibilidad y excluir 17 REVISAR de métricas de familia.
A46: CIERRE BASE MAESTRA AGRO v1.0 | B46: Resultado | C46: Regla
A47: Fecha de cierre | B47: 2026-08-26 | C47: Versión congelada.
A48: Integridad referencial | B48: 0 duplicados críticos / 0 FK inválidas | C48: APROBADO
A49: Controles integración | B49: 32/32 Resuelto | C49: APROBADO
A50: Prerrequisitos | B50: 36 relaciones; encabezados L:T restaurados | C50: CORREGIDO
A51: Asignaturas normalizadas | B51: 676 APROBADO + 17 REVISAR aceptados | C51: 17 excluidas de métricas de familia.
A52: Formativa programa | B52: 138 APROBADO + 20 contextuales aceptados | C52: 20 fuera de taxonomía FP; texto preservado.
A53: USC | B53: 0 asignaturas | C53: Mantener bloqueo de capa asignatura.
A54: Programa conjunto PT | B54: 30 asignaturas / 3 instituciones | C54: Un solo currículo.
...

Sheet 01_Datasets_Origen
A1: Codigo_Dataset | B1: ID_Curriculo_Unico | C1: Universidad | D1: Archivo_Origen | E1: Tipo_Referente | F1: Decision_Integracion | G1: Aptitud_Estructural | H1: Restriccion_Principal | I1: Cluster_Programa_Conjunto | J1: Nivel_Marco_Comparativo | K1: Alcance_Dataset | L1: Elegible_Estructura | M1: Elegible_Creditos | N1: Elegible_Contenidos | O1: Elegible_Carga | P1: Elegible_Formativa_Asignatura | Q1: Completitud_Creditos | R1: Completitud_Periodo | S1: Completitud_Fuente_Asignatura | T1: Formativa_Asignatura_Con_Dato | U1: N_Asignaturas_Origen | V1: N_Fuentes_Origen | W1: N_Evidencias_Origen | X1: N_Controles_QC_Origen
A2: UPM | B2: CUR_AGRO_UPM | C2: Universidad Politécnica de Madrid (ETSIAAB) | D2: UPM_Extractor_v1_1_Agro_Grado_Ingenieria_Alimentaria_20IA_2026_27_AUDITADO.xlsx | E2: Título completo comparable | F2: INTEGRAR | G2: APTA PARA BASE MAESTRA | H2: Sin restricción estructural; mantener limitación de contenidos/carga donde la fuente no publica guías granulares. | J2: Grado/Bachelor | K2: Programa completo | L2: Sí | M2: Sí | N2: No | O2: No | P2: Condicional | Q2: 1 | R2: 1 | S2: 1 | T2: 1 | U2: 53 | V2: 9 | W2: 107 | X2: 10
A3: USAL | B3: CUR_AGRO_USAL | C3: Universidad de Salamanca | D3: USAL_Agro_Grado_Ingenieria_Agroalimentaria_Plan_2026_AUDITADO.xlsx | E3: Título completo comparable | F3: INTEGRAR | G3: APTA PARA BASE MAESTRA | H3: No sumar catálogo optativo completo; usar requisito curricular. | J3: Grado/Bachelor | K3: Programa completo | L3: Sí | M3: Sí | N3: No | O3: No | P3: No | Q3: 1 | R3: 1 | S3: 1 | T3: 0 | U3: 41 | V3: 2 | W3: 47 | X3: 6
A4: USC | B4: CUR_AGRO_USC | C4: Universidade de Santiago de Compostela (EPS Lugo) | D4: USC_Agro_Grao_Enxenaria_Agricola_Agroalimentaria_IAA_AUDITADO.xlsx | E4: Título completo / especialidad IAA | F4: NO INTEGRAR ASIGNATURAS | G4: NO APTA AÚN | H4: Conservar programa, perfil y especialidad; completar tabla de asignaturas antes de análisis curricular. | J4: Grado/Bachelor | K4: Especialidad | L4: No | M4: No | N4: No | O4: No | P4: No | Q4: 0 | R4: 0 | S4: 0 | T4: 0 | U4: 0 | V4: 2 | W4: 5 | X4: 6
A5: UPC | B5: CUR_AGRO_UPC | C5: Universitat Politècnica de Catalunya (EEABB) | D5: UPC_Agro_Grau_Enginyeria_Alimentaria_2026_27_AUDITADO.xlsx | E5: Título completo comparable | F5: INTEGRAR | G5: APTA PARA BASE MAESTRA | H5: Distinguir oferta optativa de requisito efectivo. | J5: Grado/Bachelor | K5: Programa completo | L5: Sí | M5: Sí | N5: No | O5: No | P5: No | Q5: 1 | R5: 1 | S5: 1 | T5: 0 | U5: 45 | V5: 1 | W5: 51 | X5: 5
A6: SEVILLA | B6: CUR_AGRO_SEVILLA | C6: Universidad de Sevilla | D6: US_Agro_Grado_Ingenieria_Agricola_Explotaciones_Agropecuarias_AUDITADO.xlsx | E6: Título completo, comparabilidad parcial | F6: INTEGRAR CON BANDERA | G6: APTA PARA BASE MAESTRA | H6: Útil como referente agrario; no tratar como equivalente directo de Ingeniería Alimentaria/Agroindustria. | J6: Grado/Bachelor | K6: Programa completo | L6: Sí | M6: Sí | N6: No | O6: No | P6: No | Q6: 1 | R6: 1 | S6: 1 | T6: 0 | U6: 40 | V6: 3 | W6: 43 | X6: 5
A7: UCO | B7: CUR_AGRO_UCO | C7: Universidad de Córdoba | D7: UCO_Agro_Grado_Ingenieria_Agroalimentaria_Mencion_Ingenieria_Alimentaria_2026_27_AUDITADO.xlsx | E7: Título completo / mención Ingeniería Alimentaria | F7: INTEGRAR | G7: APTA PARA BASE MAESTRA | H7: Alta calidad estructural; cobertura formativa de asignatura disponible en un subconjunto de guías 2026/27. | J7: Grado/Bachelor | K7: Mención / especialidad | L7: Sí | M7: Sí | N7: Condicional | O7: Condicional | P7: Condicional | Q7: 1 | R7: 1 | S7: 1 | T7: 7 | U7: 43 | V7: 11 | W7: 52 | X7: 7
A8: UMH | B8: CUR_AGRO_UMH | C8: Universidad Miguel Hernández | D8: UMH_Agro_Grado_Ingenieria_Agroalimentaria_Agroambiental_IAA_2026_27_AUDITADO.xlsx | E8: Título completo / segunda atribución IAA | F8: INTEGRAR CON RESTRICCIÓN | G8: APTA SOLO COMO REFERENCIA PARCIAL | H8: Excluir de análisis cuantitativo de ECTS por asignatura hasta recuperar créditos granulares; estructura y perfil sí son utilizables. | J8: Grado/Bachelor | K8: Itinerario / segunda atribución | L8: Sí | M8: No | N8: No | O8: No | P8: No | Q8: 0.023255814 | R8: 1 | S8: 1 | T8: 0 | U8: 43 | V8: 5 | W8: 51 | X8: 7
A9: ENSAIA | B9: CUR_AGRO_ENSAIA | C9: ENSAIA – Université de Lorraine | D9: ENSAIA_Agro_Ingenieur_Industries_Alimentaires_S5_S10_AUDITADO.xlsx | E9: Diplôme d'Ingénieur — nivel master | F9: INTEGRAR COMO REFERENCIA | G9: APTA SOLO COMO REFERENCIA PARCIAL | H9: Usar horas y estructura; no comparar ECTS por asignatura ni nivel académico como si fuera grado/bachelor. | J9: Ingénieur/Master | K9: Programa declarado — cobertura parcial del dataset | L9: Sí | M9: No | N9: No | O9: Condicional | P9: No | Q9: 0 | R9: 1 | S9: 1 | T9: 0 | U9: 76 | V9: 4 | W9: 84 | X9: 8
A10: IARA | B10: CUR_AGRO_IARA | C10: L'Institut Agro Rennes-Angers | D10: Institut_Agro_Rennes_Angers_Agro_Ingenieur_Alimentation_AUDITADO.xlsx | E10: Diplôme d'Ingénieur — nivel master | F10: INTEGRAR COMO REFERENCIA | G10: APTA SOLO COMO REFERENCIA PARCIAL | H10: Cobertura curricular parcial; usar bloques, prácticas y perfil, no agregados ECTS por asignatura. | J10: Ingénieur/Master | K10: Programa declarado — cobertura parcial del dataset | L10: Sí | M10: No | N10: No | O10: Condicional | P10: No | Q10: 0.066666667 | R10: 1 | S10: 1 | T10: 0 | U10: 30 | V10: 3 | W10: 34 | X10: 5
A11: ONIRIS | B11: CUR_AGRO_ONIRIS | C11: ONIRIS Nantes | D11: ONIRIS_Agro_Ingenieur_Agroalimentaire_ING2_AUDITADO.xlsx | E11: Diplôme d'Ingénieur — nivel master | F11: INTEGRAR CON BANDERA | G11: APTA CON BANDERAS | H11: Muy valioso para resultados/competencias y S7–S8; análisis debe respetar nivel master y cobertura parcial del ciclo. | J11: Ingénieur/Master | K11: Programa completo | L11: Sí | M11: Sí | N11: Condicional | O11: Condicional | P11: Condicional | Q11: 0.94736842 | R11: 1 | S11: 1 | T11: 2 | U11: 19 | V11: 2 | W11: 23 | X11: 5
A12: AGROPARISTECH | B12: CUR_AGRO_AGROPARISTECH | C12: AgroParisTech | D12: AgroParisTech_Agro_Domaine2_Parcours_Ingenierie_Aliments_AUDITADO.xlsx | E12: Segmento 2A D2 de Diplôme d'Ingénieur | F12: INTEGRAR COMO SEGMENTO | G12: APTA SOLO COMO REFERENCIA PARCIAL | H12: No tratar los 8 registros como diploma completo; ID debe indicar segmento curricular 2A/D2. | J12: Ingénieur/Master | K12: Segmento curricular | L12: Sí | M12: No | N12: No | O12: Condicional | P12: Condicional | Q12: 0.125 | R12: 1 | S12: 1 | T12: 3 | U12: 8 | V12: 5 | W12: 12 | X12: 5
A13: IAD | B13: CUR_AGRO_IAD | C13: L'Institut Agro Dijon | D13: Institut_Agro_Dijon_Agro_Ingenieur_Alimentation_AUDITADO.xlsx | E13: Diplôme d'Ingénieur — nivel master | F13: INTEGRAR COMO REFERENCIA | G13: APTA SOLO COMO REFERENCIA PARCIAL | H13: Sin ECTS granulares suficientes; conservar proyectos, stages y módulos publicados. | J13: Ingénieur/Master | K13: Programa declarado — cobertura parcial del dataset | L13: Sí | M13: No | N13: No | O13: Condicional | P13: No | Q13: 0 | R13: 1 | S13: 1 | T13: 0 | U13: 13 | V13: 2 | W13: 17 | X13: 5
... A15: PURPAN | B15: CUR_AGRO_PURPAN | C15: École d'Ingénieurs de PURPAN | D15: PURPAN_Agro_Cursus_Ingenieur_2026_27_AUDITADO.xlsx | E15: Diplôme d'Ingénieur — nivel master | F15: INTEGRAR CON BANDERA | G15: APTA CON BANDERAS | H15: 80% de créditos granulares en registros; no forzar reconciliación donde la web agrupa experiencias. | J15: Ingénieur/Master | K15: Programa completo | L15: Sí | M15: Condicional | N15: Condicional | O15: No | P15: No | Q15: 0.8 | R15: 1 | S15: 1 | T15: 0 | U15: 25 | V15: 3 | W15: 29 | X15: 6
A16: IPB | B16: CUR_AGRO_PT_EA_JOINT_IPB_IPL_IPVC | C16: Instituto Politécnico de Bragança | D16: IPB_ESA_Agro_Licenciatura_Engenharia_Alimentar_Conjunta_AUDITADO.xlsx | E16: Licenciatura conjunta IPB–IPLeiria–IPVC | F16: INTEGRAR COMO PROGRAMA CONJUNTO | G16: APTA PARA BASE MAESTRA | H16: No contar como currículo independiente; relacionar una sola malla conjunta con tres instituciones. | I16: JOINT_EA_PT | J16: Grado/Bachelor | K16: Programa conjunto completo | L16: Sí | M16: Sí | N16: No | O16: Sí | P16: No | Q16: 1 | R16: 1 | S16: 1 | T16: 0 | U16: 30 | V16: 3 | W16: 37 | X16: 5
A17: IPLEIRIA | B17: CUR_AGRO_PT_EA_JOINT_IPB_IPL_IPVC | C17: Politécnico de Leiria | D17: IPLeiria_Agro_Licenciatura_Engenharia_Alimentar_Conjunta_AUDITADO.xlsx | E17: Licenciatura conjunta IPB–IPLeiria–IPVC | F17: INTEGRAR COMO PROGRAMA CONJUNTO | G17: APTA PARA BASE MAESTRA | H17: No contar como currículo independiente; relacionar una sola malla conjunta con tres instituciones. | I17: JOINT_EA_PT | J17: Grado/Bachelor | K17: Programa conjunto completo | L17: Sí | M17: Sí | N17: No | O17: Sí | P17: No | Q17: 1 | R17: 1 | S17: 1 | T17: 0 | U17: 30 | V17: 3 | W17: 37 | X17: 5
A18: IPVC | B18: CUR_AGRO_PT_EA_JOINT_IPB_IPL_IPVC | C18: Instituto Politécnico de Viana do Castelo | D18: IPVC_Agro_Licenciatura_Engenharia_Alimentar_Conjunta_AUDITADO.xlsx | E18: Licenciatura conjunta IPB–IPLeiria–IPVC | F18: INTEGRAR COMO PROGRAMA CONJUNTO | G18: APTA PARA BASE MAESTRA | H18: No contar como currículo independiente; relacionar una sola malla conjunta con tres instituciones. | I18: JOINT_EA_PT | J18: Grado/Bachelor | K18: Programa conjunto completo | L18: Sí | M18: Sí | N18: No | O18: Sí | P18: No | Q18: 1 | R18: 1 | S18: 1 | T18: 0 | U18: 30 | V18: 3 | W18: 37 | X18: 5
A19: ISA | B19: CUR_AGRO_ISA | C19: Instituto Superior de Agronomia – Universidade de Lisboa | D19: ISA_Universidade_Lisboa_Agro_Licenciatura_Engenharia_Alimentar_2026_27_AUDITADO.xlsx | E19: Licenciatura completa comparable | F19: INTEGRAR | G19: APTA PARA BASE MAESTRA | H19: Malla completa con ECTS y horas de contacto. | J19: Grado/Bachelor | K19: Programa completo | L19: Sí | M19: Sí | N19: No | O19: Sí | P19: No | Q19: 1 | R19: 1 | S19: 1 | T19: 0 | U19: 35 | V19: 3 | W19: 40 | X19: 5
A20: ESAV | B20: CUR_AGRO_ESAV | C20: Instituto Politécnico de Viseu – ESAV | D20: IPV_ESAV_Agro_Licenciatura_Engenharia_Alimentar_2026_27_AUDITADO.xlsx | E20: Licenciatura completa comparable | F20: INTEGRAR | G20: APTA PARA BASE MAESTRA | H20: Nuevo plan 2026/27 completo con ECTS y horas de contacto. | J20: Grado/Bachelor | K20: Programa completo | L20: Sí | M20: Sí | N20: No | O20: Sí | P20: No | Q20: 1 | R20: 1 | S20: 1 | T20: 0 | U20: 35 | V20: 1 | W20: 42 | X20: 5
A21: UNIBO | B21: CUR_AGRO_UNIBO | C21: Università di Bologna | D21: Universita_Bologna_Agro_Tecnologie_Alimentari_2026_27_AUDITADO.xlsx | E21: Laurea L-26 completa comparable | F21: INTEGRAR | G21: APTA PARA BASE MAESTRA | H21: Excluir de oferta activa las actividades marcadas non attivo; evitar doble conteo de cursos integrados. | J21: Grado/Bachelor | K21: Programa completo | L21: Sí | M21: Sí | N21: No | O21: No | P21: Condicional | Q21: 1 | R21: 1 | S21: 1 | T21: 2 | U21: 39 | V21: 3 | W21: 43 | X21: 7
A22: UNIFG | B22: CUR_AGRO_UNIFG | C22: Università degli Studi di Foggia | D22: Universita_Foggia_Agro_Scienze_Tecnologie_Alimentari_2026_27_AUDITADO.xlsx | E22: Laurea L-26 completa comparable | F22: INTEGRAR | G22: APTA PARA BASE MAESTRA | H22: Regolamento 2026/27 granular; cursos integrados deben permanecer como una unidad con componentes. | J22: Grado/Bachelor | K22: Programa completo | L22: Sí | M22: Sí | N22: Condicional | O22: Condicional | P22: Condicional | Q22: 1 | R22: 1 | S22: 1 | T22: 7 | U22: 25 | V22: 3 | W22: 36 | X22: 7
A23: UNICUSANO | B23: CUR_AGRO_UNICUSANO | C23: Università Niccolò Cusano | D23: Unicusano_Agro_Ingegneria_Industriale_Curriculum_Agroindustriale_2025_26_AUDITADO.xlsx | E23: Laurea L-9 curriculum Agroindustriale | F23: INTEGRAR CON BANDERA | G23: APTA PARA BASE MAESTRA | H23: Versión oficial recuperada 2025/26; conservar inconsistencia de propedeuticità sin inventar equivalencia. | J23: Grado/Bachelor | K23: Programa completo | L23: Sí | M23: Sí | N23: No | O23: No | P23: No | Q23: 1 | R23: 1 | S23: 1 | T23: 0 | U23: 23 | V23: 2 | W23: 28 | X23: 7
A24: HOHENHEIM | B24: CUR_AGRO_HOHENHEIM | C24: Universität Hohenheim | D24: Universitat_Hohenheim_Agro_Food_Science_Biotechnology_2026_27_AUDITADO.xlsx | E24: B.Sc. completo comparable | F24: INTEGRAR CON BANDERA | G24: APTA PARA BASE MAESTRA | H24: Distinguir módulos vigentes de detalles provenientes del archivo institucional histórico. | J24: Grado/Bachelor | K24: Programa completo | L24: Sí | M24: Sí | N24: No | O24: Condicional | P24: Condicional | Q24: 1 | R24: 1 | S24: 1 | T24: 3 | U24: 32 | V24: 6 | W24: 38 | X24: 7
A25: TUM | B25: CUR_AGRO_TUM | C25: Technische Universität München | D25: TUM_Agro_BSc_Food_Technology_2026_AUDITADO.xlsx | E25: B.Sc. completo comparable | F25: INTEGRAR CON BANDERA | G25: APTA PARA BASE MAESTRA | H25: Curriculum actualmente enlazado es válido por cohorte desde WiSe 23/24; no etiquetarlo como PDF emitido en 2026. | J25: Grado/Bachelor | K25: Programa completo | L25: Sí | M25: Sí | N25: No | O25: No | P25: No | Q25: 1 | R25: 1 | S25: 1 | T25: 0 | U25: 31 | V25: 4 | W25: 40 | X25: 8
A26: EPN | B26: CUR_AGRO_EPN | C26: Escuela Politécnica Nacional | D26: EPN_AGRO_Dataset_Comparativo_Integrable_v1_0.xlsx | E26: Currículo objetivo comparable | F26: INTEGRAR COMO TARGET | G26: APTA PARA COMPARACIÓN CON BANDERAS | H26: TARGET_EPN; NR se filtra por dimensión. | J26: Grado/Bachelor | K26: Programa completo | L26: Sí | M26: Sí | N26: Condicional | O26: Sí | P26: Condicional | Q26: 1 | R26: 1 | S26: 1 | T26: 1 | U26: 60 | V26: 8 | W26: 140 | X26: 14

Sheet 02_Universidades
A1: Codigo_Dataset | B1: ID_Curriculo_Unico | C1: ID_Universidad | D1: Universidad_oficial | E1: Nombre_corto | F1: Pais | G1: Ciudad | H1: Region | I1: Tipo_institucion | J1: Grupo_referencia | K1: Ranking_sistema | L1: Ranking_anio | M1: Ranking_posicion | N1: ID_Fuente_principal | O1: Observaciones
A2: UPM | B2: CUR_AGRO_UPM | C2: UPM | D2: Universidad Politécnica de Madrid | E2: UPM | F2: España | G2: Madrid | I2: NR | K2: NR | L2: NR | M2: NR | N2: UPM_20IA_2026_27_F002 | O2: Unidad académica: E.T.S. de Ingeniería Agronómica, Alimentaria y de Biosistemas. Dataset exclusivamente AGRO.
A3: USAL | B3: CUR_AGRO_USAL | C3: USAL | D3: Universidad de Salamanca | E3: USAL | F3: España | G3: Zamora | I3: NR | J3: Agroindustria internacional | K3: NR | L3: NR | M3: NR | N3: USAL_GRADO_EN_INGENIER_A_AGROALIMENTARIA_P_F001
A4: USC | B4: CUR_AGRO_USC | C4: USC | D4: Universidade de Santiago de Compostela | E4: USC | F4: España | G4: Lugo | I4: NR | J4: Agroindustria internacional | K4: NR | L4: NR | M4: NR | N4: USC_GRAO_EN_ENXE_AR_A_AGR_COLA_E_AGROALIME_F001
A5: UPC | B5: CUR_AGRO_UPC | C5: UPC | D5: Universitat Politècnica de Catalunya | E5: UPC | F5: España | G5: Castelldefels | I5: NR | J5: Agroindustria internacional | K5: NR | L5: NR | M5: NR | N5: UPC_GRAU_EN_ENGINYERIA_ALIMENT_RIA_EEABB_P_F001
A6: SEVILLA | B6: CUR_AGRO_SEVILLA | C6: US | D6: Universidad de Sevilla | E6: US | F6: España | G6: Sevilla | I6: NR | J6: Agroindustria internacional | K6: NR | L6: NR | M6: NR | N6: US_GRADO_EN_INGENIER_A_AGR_COLA_MENCI_N_EX_F001
A7: UCO | B7: CUR_AGRO_UCO | C7: UCO | D7: Universidad de Córdoba | E7: UCO | F7: España | G7: Córdoba | I7: NR | J7: Agroindustria internacional | K7: NR | L7: NR | M7: NR | N7: UCO_GRADO_EN_INGENIER_A_AGROALIMENTARIA_Y_DEL_MEDIO_RUR_F001 | O7: Dataset independiente de IQ.
A8: UMH | B8: CUR_AGRO_UMH | C8: UMH | D8: Universidad Miguel Hernández de Elche | E8: UMH | F8: España | G8: Orihuela | I8: NR | J8: Agroindustria internacional | K8: NR | L8: NR | M8: NR | N8: UMH_GRADO_EN_INGENIER_A_AGROALIMENTARIA_Y_AGROAMBIENTAL_F001 | O8: Dataset independiente de IQ.
A9: ENSAIA | B9: CUR_AGRO_ENSAIA | C9: ENSAIA | D9: ENSAIA – Université de Lorraine | E9: ENSAIA | F9: Francia | G9: Vandœuvre-lès-Nancy | I9: NR | J9: Agroindustria internacional | K9: NR | L9: NR | M9: NR | N9: ENSAIA_DIPL_ME_D_ING_NIEUR_ENSAIA_FILI_RE_INDUSTRIES_AL_F001 | O9: Dataset independiente de IQ.
A10: IARA | B10: CUR_AGRO_IARA | C10: IARA | D10: L'Institut Agro Rennes-Angers | E10: IARA | F10: Francia | G10: Rennes | I10: NR | J10: Agroindustria internacional | K10: NR | L10: NR | M10: NR | N10: IARA_DIPL_ME_D_ING_NIEUR_EN_ALIMENTATION_OFERTA_VIGENTE_F001 | O10: Dataset independiente de IQ.
A11: ONIRIS | B11: CUR_AGRO_ONIRIS | C11: ONIRIS | D11: ONIRIS Nantes | E11: ONIRIS | F11: Francia | G11: Nantes | I11: NR | J11: Agroindustria internacional | K11: NR | L11: NR | M11: NR | N11: ONIRIS_DIPL_ME_D_ING_NIEUR_ONIRIS_ORIENTATION_AGROALIME_F001 | O11: Dataset independiente de IQ.
A12: AGROPARISTECH | B12: CUR_AGRO_AGROPARISTECH | C12: AGROPARISTECH | D12: AgroParisTech | E12: AGROPARISTECH | F12: Francia | G12: Palaiseau / Paris-Saclay | I12: NR | J12: Agroindustria internacional | K12: NR | L12: NR | M12: NR | N12: AGROPARISTECH_DIPL_ME_D_ING_NIEUR_AGROPARISTECH_2A_DOMA_F001 | O12: Dataset independiente de IQ.
A13: IAD | B13: CUR_AGRO_IAD | C13: IAD | D13: L'Institut Agro Dijon | E13: IAD | F13: Francia | G13: Dijon | I13: NR | J13: Agroindustria internacional | K13: NR | L13: NR | M13: NR | N13: IAD_DIPL_ME_D_ING_NIEUR_EN_ALIMENTATION_OFERTA_INSTITUC_F001 | O13: Dataset independiente de IQ.
A14: UNILASALLE | B14: CUR_AGRO_UNILASALLE | C14: UNILASALLE | D14: UniLaSalle (Institut Polytechnique) | E14: UNILASALLE | F14: Francia | G14: Beauvais | I14: NR | J14: Agroindustria internacional | K14: NR | L14: NR | M14: NR | N14: UNILASALLE_ING_NIEUR_EN_ALIMENTATION_ET_SANT_BROCHURE_I_F001 | O14: Dataset independiente de IQ.
A15: PURPAN | B15: CUR_AGRO_PURPAN | C15: PURPAN | D15: École d'Ingénieurs de PURPAN | E15: PURPAN | F15: Francia | G15: Toulouse | I15: NR | J15: Agroindustria internacional | K15: NR | L15: NR | M15: NR | N15: PURPAN_CURSUS_ING_NIEUR_PURPAN_ORIENTATION_AGROALIMENTA_F001 | O15: Dataset independiente de IQ.
A16: IPB | B16: CUR_AGRO_PT_EA_JOINT_IPB_IPL_IPVC | C16: IPB | D16: Instituto Politécnico de Bragança — Escola Superior Agrária | E16: IPB | F16: Portugal | G16: Bragança | I16: NR | J16: Agroindustria internacional | K16: NR | L16: NR | M16: NR | N16: IPB_LICENCIATURA_EM_ENGENHARIA_ALIMENTAR_T_TULO_CONJUNT_F001 | O16: Dataset independiente de IQ.
A17: IPLEIRIA | B17: CUR_AGRO_PT_EA_JOINT_IPB_IPL_IPVC | C17: IPLEIRIA | D17: Politécnico de Leiria — Escola Superior de Turismo e Tecnologia do Mar | E17: IPLEIRIA | F17: Portugal | G17: Peniche | I17: NR | J17: Agroindustria internacional | K17: NR | L17: NR | M17: NR | N17: IPLEIRIA_LICENCIATURA_EM_ENGENHARIA_ALIMENTAR_T_TULO_CO_F001 | O17: Dataset independiente de IQ.
A18: IPVC | B18: CUR_AGRO_PT_EA_JOINT_IPB_IPL_IPVC | C18: IPVC | D18: Instituto Politécnico de Viana do Castelo — ESTG | E18: IPVC | F18: Portugal | G18: Viana do Castelo | I18: NR | J18: Agroindustria internacional | K18: NR | L18: NR | M18: NR | N18: IPVC_LICENCIATURA_EM_ENGENHARIA_ALIMENTAR_T_TULO_CONJUN_F001 | O18: Dataset independiente de IQ.
... A25: TUM | B25: CUR_AGRO_TUM | C25: TUM | D25: Technische Universität München | E25: TUM | F25: Alemania | G25: Freising | I25: NR | J25: Agroindustria internacional | K25: NR | L25: NR | M25: NR | N25: TUM_B_SC_FOOD_TECHNOLOGY_LEBENSMITTELTECHNOLOGIE_CURRIC_F001 | O25: Dataset independiente de IQ.
A26: EPN | B26: CUR_AGRO_EPN | C26: EPN | D26: Escuela Politécnica Nacional | E26: EPN | F26: Ecuador | G26: Quito | H26: Pichincha | I26: Universidad pública | J26: Currículo objetivo EPN | K26: NR | L26: NR | M26: NR | N26: EPN_AGRO_F001 | O26: TARGET_EPN; excluida de denominadores del benchmark de referencia.

Sheet 03_Curriculos
A1: ID_Curriculo_Unico | B1: Codigo_Dataset_Canonico | C1: ID_Programa_Origen_Canonico | D1: Nombre_Programa_Original | E1: Nombre_Programa_Espanol | F1: Titulo_Otorgado_Original | G1: Titulo_Otorgado_Espanol | H1: Nivel_Programa_Original | I1: Nivel_Marco_Comparativo | J1: Alcance_Dataset | K1: Anio_Malla | L1: Version_Malla | M1: Duracion_Valor | N1: Duracion_Unidad | O1: Sistema_Periodos_Original | P1: Numero_Total_Periodos | Q1: Creditos_Totales | R1: Sistema_Creditos | S1: Idioma | T1: Modalidad | U1: Acreditacion_Reportada | V1: Practica_Industrial_Reportada | W1: Tesis_Reportada | X1: Proyecto_Final_Reportado | Y1: URL_Programa | Z1: N_Instituciones_Titulares | AA1: Codigos_Instituciones_Titulares | AB1: Tipo_Referente | AC1: Decision_Integracion | AD1: Aptitud_Estructural | AE1: Restriccion_Principal | AF1: Elegible_Estructura | AG1: Elegible_Creditos | AH1: Elegible_Contenidos | AI1: Elegible_Carga | AJ1: Elegible_Formativa_Asignatura
A2: CUR_AGRO_UPM | B2: UPM | C2: UPM_20IA_2026_27 | D2: Grado en Ingeniería Alimentaria | E2: Grado en Ingeniería Alimentaria | F2: Graduado/a en Ingeniería Alimentaria por la Universidad Politécnica de Madrid | G2: Graduado/a en Ingeniería Alimentaria por la Universidad Politécnica de Madrid | H2: Grado | I2: Grado/Bachelor | J2: Programa completo | K2: 2026 | L2: Plan 20IA — curso 2026/27 | M2: 4 | N2: Años | O2: Semestres | P2: 8 | Q2: 240 | R2: ECTS | S2: Español; determinadas materias pueden impartirse en inglés | T2: Presencial | U2: ABET; EUR-ACE | V2: Sí | W2: NR | X2: Sí | Y2: https://www.etsiaab.upm.es/Docencia/Grados/IngAlimentaria | Z2: 1 | AA2: UPM | AB2: Título completo comparable | AC2: INTEGRAR | AD2: APTA PARA BASE MAESTRA | AE2: Sin restricción estructural; mantener limitación de contenidos/carga donde la fuente no publica guías granulares. | AF2: Sí | AG2: Sí | AH2: No | AI2: No | AJ2: Condicional
A3: CUR_AGRO_USAL | B3: USAL | C3: USAL_GRADO_EN_INGENIER_A_AGROALIMENTARIA_P | D3: Grado en Ingeniería Agroalimentaria — Plan 2026 | E3: Grado en Ingeniería Agroalimentaria — Plan 2026 | F3: Graduado/a en Ingeniería Agroalimentaria | G3: Graduado/a en Ingeniería Agroalimentaria | H3: Grado | I3: Grado/Bachelor | J3: Programa completo | K3: 2026 | L3: Plan 2026 / curso 2026-27 | M3: 4 | N3: Años | O3: Semestres | P3: 8 | Q3: 240 | R3: ECTS | S3: Español | T3: Presencial | U3: Habilitante para la profesión regulada de Ingeniero Técnico Agrícola | V3: NR | W3: NR | X3: Sí | Y3: https://usal.es/grado-en-ingenieria-agroalimentaria | Z3: 1 | AA3: USAL | AB3: Título completo comparable | AC3: INTEGRAR | AD3: APTA PARA BASE MAESTRA | AE3: No sumar catálogo optativo completo; usar requisito curricular. | AF3: Sí | AG3: Sí | AH3: No | AI3: No | AJ3: No
A4: CUR_AGRO_USC | B4: USC | C4: USC_GRAO_EN_ENXE_AR_A_AGR_COLA_E_AGROALIME | D4: Grao en Enxeñaría Agrícola e Agroalimentaria — itinerario Industrias Agrarias e Alimentarias | E4: Grao en Enxeñaría Agrícola e Agroalimentaria — itinerario Industrias Agrarias e Alimentarias | F4: Graduado/a en Enxeñaría Agrícola e Agroalimentaria | G4: Graduado/a en Enxeñaría Agrícola e Agroalimentaria | H4: Grado | I4: Grado/Bachelor | J4: Especialidad | K4: 2026 | L4: Plan vigente / folleto oficial actualizado | M4: 4 | N4: Años | O4: Semestres | P4: 8 | Q4: 240 | R4: ECTS | S4: Galego / Español | T4: Presencial | U4: EUR-ACE®; habilitante para Ingeniero Técnico Agrícola | V4: Sí; hasta 6 ECTS optativos reconocibles | W4: NR | X4: Sí | Y4: https://www.usc.gal/gl/estudos/graos/enxenaria-arquitectura/grao-enxenaria-agricola-agroalimentaria | Z4: 1 | AA4: USC | AB4: Título completo / especialidad IAA | AC4: NO INTEGRAR ASIGNATURAS | AD4: NO APTA AÚN | AE4: Conservar programa, perfil y especialidad; completar tabla de asignaturas antes de análisis curricular. | AF4: No | AG4: No | AH4: No | AI4: No | AJ4: No
A5: CUR_AGRO_UPC | B5: UPC | C5: UPC_GRAU_EN_ENGINYERIA_ALIMENT_RIA_EEABB_P | D5: Grau en Enginyeria Alimentària — EEABB | E5: Grau en Enginyeria Alimentària — EEABB | F5: Graduat/da en Enginyeria Alimentària | G5: Graduat/da en Enginyeria Alimentària | H5: Grado | I5: Grado/Bachelor | J5: Programa completo | K5: 2026 | L5: Plan vigente 2026-27 | M5: 4 | N5: Años | O5: Semestres | P5: 8 | Q5: 240 | R5: ECTS | S5: Catalán / Español / Inglés según asignatura | T5: Presencial | U5: Habilitante para Ingeniero Técnico Agrícola, especialidad Industrias Agrarias y Alimentarias | V5: Sí, opción de Pràctiques Externes | W5: NR | X5: Sí | Y5: https://www.upc.edu/ca/graus/enginyeria-alimentaria-castelldefels-eeabb | Z5: 1 | AA5: UPC | AB5: Título completo comparable | AC5: INTEGRAR | AD5: APTA PARA BASE MAESTRA | AE5: Distinguir oferta optativa de requisito efectivo. | AF5: Sí | AG5: Sí | AH5: No | AI5: No | AJ5: No
A6: CUR_AGRO_SEVILLA | B6: SEVILLA | C6: US_GRADO_EN_INGENIER_A_AGR_COLA_MENCI_N_EX | D6: Grado en Ingeniería Agrícola — mención Explotaciones Agropecuarias | E6: Grado en Ingeniería Agrícola — mención Explotaciones Agropecuarias | F6: Graduado/a en Ingeniería Agrícola | G6: Graduado/a en Ingeniería Agrícola | H6: Grado | I6: Grado/Bachelor | J6: Programa completo | K6: 2026 | L6: Plan vigente 2026-27 | M6: 4 | N6: Años | O6: Semestres | P6: 8 | Q6: 240 | R6: ECTS | S6: Español | T6: Presencial | U6: Habilitante para Ingeniero Técnico Agrícola | V6: Prácticas en empresas disponibles como optativa | W6: NR | X6: Sí | Y6: https://www.us.es/estudiar/que-estudiar/oferta-de-grados/grado-en-ingenieria-agricola | Z6: 1 | AA6: SEVILLA | AB6: Título completo, comparabilidad parcial | AC6: INTEGRAR CON BANDERA | AD6: APTA PARA BASE MAESTRA | AE6: Útil como referente agrario; no tratar como equivalente directo de Ingeniería Alimentaria/Agroindustria. | AF6: Sí | AG6: Sí | AH6: No | AI6: No | AJ6: No
A7: CUR_AGRO_UCO | B7: UCO | C7: UCO_GRADO_EN_INGENIER_A_AGROALIMENTARIA_Y_DEL_MEDIO_RUR | D7: Grado en Ingeniería Agroalimentaria y del Medio Rural — Mención Ingeniería Alimentaria | E7: Grado en Ingeniería Agroalimentaria y del Medio Rural — Mención Ingeniería Alimentaria | F7: Graduado/a en Ingeniería Agroalimentaria y del Medio Rural | G7: Graduado/a en Ingeniería Agroalimentaria y del Medio Rural | H7: Grado | I7: Grado/Bachelor | J7: Mención / especialidad | K7: 2026 | L7: Planificación y Guías Docentes 2026/27 — Mención Ingeniería Alimentaria | M7: 4 | N7: Años | O7: Semestres | P7: 8 | Q7: 240 | R7: ECTS | S7: Español | T7: Presencial | U7: Habilitante para Ingeniero Técnico Agrícola; mención Ingeniería Alimentaria | V7: NR | W7: NR | X7: Sí | Y7: https://www.uco.es/etsiam/es/planificacion-guias-agroalimentaria | Z7: 1 | AA7: UCO | AB7: Título completo / mención Ingeniería Alimentaria | AC7: INTEGRAR | AD7: APTA PARA BASE MAESTRA | AE7: Alta calidad estructural; cobertura formativa de asignatura disponible en un subconjunto de guías 2026/27. | AF7: Sí | AG7: Sí | AH7: Condicional | AI7: Condicional | AJ7: Condicional
A8: CUR_AGRO_UMH | B8: UMH | C8: UMH_GRADO_EN_INGENIER_A_AGROALIMENTARIA_Y_AGROAMBIENTAL | D8: Grado en Ingeniería Agroalimentaria y Agroambiental — segunda atribución Industrias Agrarias y Alimentarias | E8: Grado en Ingeniería Agroalimentaria y Agroambiental — segunda atribución Industrias Agrarias y Alimentarias | F8: Graduado/a en Ingeniería Agroalimentaria y Agroambiental | G8: Graduado/a en Ingeniería Agroalimentaria y Agroambiental | H8: Grado | I8: Grado/Bachelor | J8: Itinerario / segunda atribución | K8: 2026 | L8: Estructura y curso 2026/27 — itinerario/segunda atribución Industrias Agrarias y Alimentarias | M8: 4 | N8: Años | O8: Semestres | P8: 8 | Q8: 240 | R8: ECTS | S8: Español | T8: Presencial | U8: Habilitante; permite segunda atribución en Industrias Agrarias y Alimentarias | V8: NR | W8: NR | X8: Sí | Y8: https://ingagroalimentaria.umh.es/ | Z8: 1 | AA8: UMH | AB8: Título completo / segunda atribución IAA | AC8: INTEGRAR CON RESTRICCIÓN | AD8: APTA SOLO COMO REFERENCIA PARCIAL | AE8: Excluir de análisis cuantitativo de ECTS por asignatura hasta recuperar créditos granulares; estructura y perfil sí son utilizables. | AF8: Sí | AG8: No | AH8: No | AI8: No | AJ8: No
A9: CUR_AGRO_ENSAIA | B9: ENSAIA | C9: ENSAIA_DIPL_ME_D_ING_NIEUR_ENSAIA_FILI_RE_INDUSTRIES_AL | D9: Diplôme d'Ingénieur ENSAIA — Filière Industries Alimentaires | E9: Diplôme d'Ingénieur ENSAIA — Filière Industries Alimentaires | F9: Ingénieur ENSAIA – Industries Alimentaires | G9: Ingénieur ENSAIA – Industries Alimentaires | H9: Diplôme d'ingénieur — grade de master | I9: Ingénieur/Master | J9: Programa declarado — cobertura parcial del dataset | K9: 2026 | L9: Syllabus officiel Industries Alimentaires S5–S8 + cursus S5–S10 | M9: 3 | N9: Años de ciclo ingénieur | O9: Semestres | P9: 6 | Q9: NR | R9: ECTS | S9: Francés | T9: Presencial | U9: Diplôme d'ingénieur, grade de master | V9: Tres stages, 40 semanas en total: stage ouvrier, stage internacional obligatorio y stage final de 6 meses | W9: NR | X9: Sí | Y9: https://ensaia.univ-lorraine.fr/fr/content/incoming-students | Z9: 1 | AA9: ENSAIA | AB9: Diplôme d'Ingénieur — nivel master | AC9: INTEGRAR COMO REFERENCIA | AD9: APTA SOLO COMO REFERENCIA PARCIAL | AE9: Usar horas y estructura; no comparar ECTS por asignatura ni nivel académico como si fuera grado/bachelor. | AF9: Sí | AG9: No | AH9: No | AI9: Condicional | AJ9: No
A10: CUR_AGRO_IARA | B10: IARA | C10: IARA_DIPL_ME_D_ING_NIEUR_EN_ALIMENTATION_OFERTA_VIGENTE | D10: Diplôme d'Ingénieur en Alimentation | E10: Diplôme d'Ingénieur en Alimentation | F10: Ingénieur en Alimentation | G10: Ingénieur en Alimentation | H10: Diplôme d'ingénieur (grade de master) | I10: Ingénieur/Master | J10: Programa declarado — cobertura parcial del dataset | K10: 2026 | L10: Oferta vigente 2026 + estructura oficial del cursus Ingénieur en alimentation | M10: 5 | N10: Años post-bac | O10: Semestres | P10: 10 | Q10: 300 | R10: ECTS | S10: Francés | T10: Presencial / apprentissage selon voie | U10: Diplôme d'ingénieur | V10: Sí; 5–6 meses en S5 y 6 meses en S10 | W10: NR | X10: Sí | Y10: https://www.institut-agro-rennes-angers.fr/formation/ingenieurs/ingenieur-en-alimentation | Z10: 1 | AA10: IARA | AB10: Diplôme d'Ingénieur — nivel master | AC10: INTEGRAR COMO REFERENCIA | AD10: APTA SOLO COMO REFERENCIA PARCIAL | AE10: Cobertura curricular parcial; usar bloques, prácticas y perfil, no agregados ECTS por asignatura. | AF10: Sí | AG10: No | AH10: No | AI10: Condicional | AJ10: No
A11: CUR_AGRO_ONIRIS | B11: ONIRIS | C11: ONIRIS_DIPL_ME_D_ING_NIEUR_ONIRIS_ORIENTATION_AGROALIME | D11: Diplôme d'Ingénieur Oniris — orientation agroalimentaire/biotechnologies | E11: Diplôme d'Ingénieur Oniris — orientation agroalimentaire/biotechnologies | F11: Ingénieur Oniris | G11: Ingénieur Oniris | H11: Diplôme d'ingénieur (grade de master) | I11: Ingénieur/Master | J11: Programa completo | K11: 2026 | L11: Guide pédagogique ING2 2025-26 + estructura institucional vigente | M11: 3 | N11: Años de cycle ingénieur | O11: Semestres | P11: 6 | Q11: 180 | R11: ECTS | S11: Francés | T11: Presencial | U11: Diplôme d'ingénieur | V11: Sí; stages y stage final | W11: NR | X11: Sí | Y11: https://www.oniris-nantes.fr/formations/la-formation-ingenieur | Z11: 1 | AA11: ONIRIS | AB11: Diplôme d'Ingénieur — nivel master | AC11: INTEGRAR CON BANDERA | AD11: APTA CON BANDERAS | AE11: Muy valioso para resultados/competencias y S7–S8; análisis debe respetar nivel master y cobertura parcial del ciclo. | AF11: Sí | AG11: Sí | AH11: Condicional | AI11: Condicional | AJ11: Condicional
A12: CUR_AGRO_AGROPARISTECH | B12: AGROPARISTECH | C12: AGROPARISTECH_DIPL_ME_D_ING_NIEUR_AGROPARISTECH_2A_DOMA | D12: Diplôme d'Ingénieur AgroParisTech — 2A Domaine Ingénierie des aliments, biomolécules et énergie / parcours Ingénierie des aliments | E12: Diplôme d'Ingénieur AgroParisTech — 2A Domaine Ingénierie des aliments, biomolécules et énergie / parcours Ingénierie des aliments | F12: Ingénieur AgroParisTech | G12: Ingénieur AgroParisTech | H12: Diplôme d'ingénieur (grade de master) — segmento de especialización 2A | I12: Ingénieur/Master | J12: Segmento curricular | K12: 2026 | L12: Catalogue SynapseS détaillé 2025-26; catalogue 2026-27 disponible mais détail D2 indexé en 2025-26 | M12: 1 | N12: Año curricular seleccionado (2A) | O12: Semestres | P12: 2 | Q12: 60 | R12: ECTS | S12: Francés | T12: Presencial | U12: Diplôme d'ingénieur | V12: Sí | W12: NR | X12: NR | Y12: https://synapses.agroparistech.fr/catalogue/2025-2026/ue/2000/2A-D2-domaine-ingenierie-des-aliments-biomolecules-et-energie?from=D1 | Z12: 1 | AA12: AGROPARISTECH | AB12: Segmento 2A D2 de Diplôme d'Ingénieur | AC12: INTEGRAR COMO SEGMENTO | AD12: APTA SOLO COMO REFERENCIA PARCIAL | AE12: No tratar los 8 registros como diploma completo; ID debe indicar segmento curricular 2A/D2. | AF12: Sí | AG12: No | AH12: No | AI12: Condicional | AJ12: Condicional
A13: CUR_AGRO_IAD | B13: IAD | C13: IAD_DIPL_ME_D_ING_NIEUR_EN_ALIMENTATION_OFERTA_INSTITUC | D13: Diplôme d'Ingénieur en Alimentation | E13: Diplôme d'Ingénieur en Alimentation | F13: Ingénieur en Alimentation | G13: Ingénieur en Alimentation | H13: Diplôme d'ingénieur (grade de master) | I13: Ingénieur/Master | J13: Programa declarado — cobertura parcial del dataset | K13: 2026 | L13: Oferta institucional vigente 2026 | M13: 3 | N13: Años tras Bac+2 | O13: Semestres | P13: 6 | Q13: NR | R13: ECTS | S13: Francés | T13: Presencial / apprentissage selon voie | U13: Diplôme d'ingénieur | V13: Sí; 4 semanas + 16 semanas internacional + 20–24 semanas finales | W13: NR | X13: Sí | Y13: https://institut-agro-dijon.fr/formations/ingenieur-en-alimentation | Z13: 1 | AA13: IAD | AB13: Diplôme d'Ingénieur — nivel master | AC13: INTEGRAR COMO REFERENCIA | AD13: APTA SOLO COMO REFERENCIA PARCIAL | AE13: Sin ECTS granulares suficientes; conservar proyectos, stages y módulos publicados. | AF13: Sí | AG13: No | AH13: No | AI13: Condicional | AJ13: No
A14: CUR_AGRO_UNILASALLE | B14: UNILASALLE | C14: UNILASALLE_ING_NIEUR_EN_ALIMENTATION_ET_SANT_BROCHURE_I | D14: Ingénieur en Alimentation et Santé | E14: Ingénieur en Alimentation et Santé | F14: Ingénieur en Agro-Alimentation et Santé | G14: Ingénieur en Agro-Alimentation et Santé | H14: Diplôme d'ingénieur — Grade Master | I14: Ingénieur/Master | J14: Programa declarado — cobertura parcial del dataset | K14: 2026 | L14: Brochure internationale 2026-2027 + fiche synthétique du cycle ingénieur | M14: 5 | N14: Años | O14: Semestres | P14: 10 | Q14: 300 | R14: ECTS | S14: Francés / Inglés según majeure | T14: Presencial / apprentissage | U14: Diplôme d'ingénieur; 180 ECTS en 6 semestres del ciclo | V14: 15 meses de stages a lo largo del cursus; movilidad internacional obligatoria al inicio de 3.er año | W14: NR | X14: Sí | Y14: https://www.unilasalle.fr/formations/ingenieur-en-alimentation-et-sante-par-apprentissage | Z14: 1 | AA14: UNILASALLE | AB14: Diplôme d'Ingénieur — nivel master | AC14: INTEGRAR COMO REFERENCIA | AD14: APTA SOLO COMO REFERENCIA PARCIAL | AE14: La evidencia recuperada es de parcours/perfiles, no malla completa granular. | AF14: Sí | AG14: No | AH14: No | AI14: No | AJ14: No
A15: CUR_AGRO_PURPAN | B15: PURPAN | C15: PURPAN_CURSUS_ING_NIEUR_PURPAN_ORIENTATION_AGROALIMENTA | D15: Cursus Ingénieur PURPAN — orientation agroalimentaire / management industriel | E15: Cursus Ingénieur PURPAN — orientation agroalimentaire / management industriel | F15: Ingénieur de PURPAN | G15: Ingénieur de PURPAN | H15: Diplôme d'ingénieur (grade de master) | I15: Ingénieur/Master | J15: Programa completo | K15: 2026 | L15: Cursus Ingénieur + List of Courses 2026-2027 | M15: 5 | N15: Años | O15: Semestres | P15: 10 | Q15: 300 | R15: ECTS | S15: Francés | T15: Presencial / alternance | U15: CTI; grade de master | V15: Sí; múltiples stages y stage final de 6 meses | W15: NR | X15: Sí | Y15: https://www.purpan.fr/formation/cursus-ingenieur/ | Z15: 1 | AA15: PURPAN | AB15: Diplôme d'Ingénieur — nivel master | AC15: INTEGRAR CON BANDERA | AD15: APTA CON BANDERAS | AE15: 80% de créditos granulares en registros; no forzar reconciliación donde la web agrupa experiencias. | AF15: Sí | AG15: Condicional | AH15: Condicional | AI15: No | AJ15: No
A16: CUR_AGRO_PT_EA_JOINT_IPB_IPL_IPVC | B16: IPLEIRIA | C16: IPLEIRIA_LICENCIATURA_EM_ENGENHARIA_ALIMENTAR_T_TULO_CO | D16: Licenciatura em Engenharia Alimentar — título conjunto IPB/IPLeiria/IPVC | E16: Licenciatura em Engenharia Alimentar — título conjunto IPB/IPLeiria/IPVC | F16: Licenciado em Engenharia Alimentar — título conjunto | G16: Licenciado em Engenharia Alimentar — título conjunto | H16: Licenciatura (1.º ciclo) | I16: Grado/Bachelor | J16: Programa conjunto completo | K16: 2026 | L16: Plano conjunto vigente — verificado 2026 | M16: 3 | N16: Años | O16: Semestres | P16: 6 | Q16: 180 | R16: ECTS | S16: Portugués | T16: Diurno / presencial | U16: A3ES; curso conjunto; IPB declara conformidad OE/FEANI | V16: Projeto/Estágio em S6 | W16: NR | X16: Sí | Y16: https://www.ipleiria.pt/curso/licenciatura-em-engenharia-alimentar/ | Z16: 3 | AA16: IPB; IPLEIRIA; IPVC | AB16: Licenciatura conjunta IPB–IPLeiria–IPVC | AC16: INTEGRAR COMO PROGRAMA CONJUNTO | AD16: APTA PARA BASE MAESTRA | AE16: No contar como currículo independiente; relacionar una sola malla conjunta con tres instituciones. | AF16: Sí | AG16: Sí | AH16: No | AI16: Sí | AJ16: No
A17: CUR_AGRO_ISA | B17: ISA | C17: ISA_ULISBOA_LICENCIATURA_BOLONHA_EM_ENGENHARIA_ALIMENTA | D17: Licenciatura Bolonha em Engenharia Alimentar | E17: Licenciatura Bolonha em Engenharia Alimentar | F17: Licenciado em Engenharia Alimentar | G17: Licenciado em Engenharia Alimentar | H17: Licenciatura (1.º ciclo) | I17: Grado/Bachelor | J17: Programa completo | K17: 2026 | L17: Currículo 2026/2027 — Licenciatura Bolonha em Engenharia Alimentar | M17: 3 | N17: Años | O17: Semestres | P17: 6 | Q17: 180 | R17: ECTS | S17: Portugués | T17: Presencial | U17: NR | V17: Estágio de 6 ECTS | W17: NR | X17: Sí | Y17: https://fenix.isa.ulisboa.pt/degrees/lealim/curriculo | Z17: 1 | AA17: ISA | AB17: Licenciatura completa comparable | AC17: INTEGRAR | AD17: APTA PARA BASE MAESTRA | AE17: Malla completa con ECTS y horas de contacto. | AF17: Sí | AG17: Sí | AH17: No | AI17: Sí | AJ17: No
A18: CUR_AGRO_ESAV | B18: ESAV | C18: ESAV_IPV_LICENCIATURA_EM_ENGENHARIA_ALIMENTAR_NOVO_PLAN | D18: Licenciatura em Engenharia Alimentar | E18: Licenciatura em Engenharia Alimentar | F18: Licenciado em Engenharia Alimentar | G18: Licenciado em Engenharia Alimentar | H18: Licenciatura (1.º ciclo) | I18: Grado/Bachelor | J18: Programa completo | K18: 2026 | L18: Novo plano 2026/27 | M18: 3 | N18: Años | O18: Semestres | P18: 6 | Q18: 180 | R18: ECTS | S18: Portugués | T18: Diurno | U18: A3ES: acreditado 6 anos (27-05-2022) | V18: Estágio em contexto laboral — 13 ECTS / 360 h | W18: NR | X18: Sí | Y18: https://esav.ipv.pt/estudar/engenharia-alimentar/ | Z18: 1 | AA18: ESAV | AB18: Licenciatura completa comparable | AC18: INTEGRAR | AD18: APTA PARA BASE MAESTRA | AE18: Nuevo plan 2026/27 completo con ECTS y horas de contacto. | AF18: Sí | AG18: Sí | AH18: No | AI18: Sí | AJ18: No
A19: CUR_AGRO_UNIBO | B19: UNIBO | C19: UNIBO_LAUREA_IN_TECNOLOGIE_ALIMENTARI_CODICE_6629_PIANO | D19: Laurea in Tecnologie Alimentari — codice 6629 | E19: Laurea in Tecnologie Alimentari — codice 6629 | F19: Laurea in Tecnologie Alimentari | G19: Laurea in Tecnologie Alimentari | H19: Laurea triennale L-26 | I19: Grado/Bachelor | J19: Programa completo | K19: 2026 | L19: Piano didattico A.A. 2026/2027 — immatricolati 2026-27 | M19: 3 | N19: Años | O19: Semestres | P19: 6 | Q19: 180 | R19: CFU/ECTS | S19: Italiano | T19: Presencial | U19: NR | V19: Tirocinio curriculare 5 CFU; opciones integrativas y preparación final | W19: NR | X19: Sí | Y19: https://corsi.unibo.it/laurea/TecnologieAlimentari/insegnamenti/piano/2026/6629/000/000/2026 | Z19: 1 | AA19: UNIBO | AB19: Laurea L-26 completa comparable | AC19: INTEGRAR | AD19: APTA PARA BASE MAESTRA | AE19: Excluir de oferta activa las actividades marcadas non attivo; evitar doble conteo de cursos integrados. | AF19: Sí | AG19: Sí | AH19: No | AI19: No | AJ19: Condicional
A20: CUR_AGRO_UNIFG | B20: UNIFG | C20: UNIFG_LAUREA_IN_SCIENZE_E_TECNOLOGIE_ALIMENTARI_CODICE_ | D20: Laurea in Scienze e Tecnologie Alimentari — codice 1252 | E20: Laurea in Scienze e Tecnologie Alimentari — codice 1252 | F20: Laurea in Scienze e Tecnologie Alimentari | G20: Laurea in Scienze e Tecnologie Alimentari | H20: Laurea triennale L-26 | I20: Grado/Bachelor | J20: Programa completo | K20: 2026 | L20: Regolamento didattico A.A. 2026/2027 — programmazione semestrale | M20: 3 | N20: Años | O20: Semestres | P20: 6 | Q20: 180 | R20: CFU/ECTS | S20: Italiano | T20: Convenzionale | U20: NR | V20: Tirocinio 10 CFU / 250 h | W20: NR | X20: Sí | Y20: https://www.unifg.it/it/studiare/corsi-di-laurea/lauree-triennali-e-ciclo-unico/scienze-e-tecnologie-alimentari | Z20: 1 | AA20: UNIFG | AB20: Laurea L-26 completa comparable | AC20: INTEGRAR | AD20: APTA PARA BASE MAESTRA | AE20: Regolamento 2026/27 granular; cursos integrados deben permanecer como una unidad con componentes. | AF20: Sí | AG20: Sí | AH20: Condicional | AI20: Condicional | AJ20: Condicional
A21: CUR_AGRO_UNICUSANO | B21: UNICUSANO | C21: UNICUSANO_LAUREA_TRIENNALE_IN_INGEGNERIA_INDUSTRIALE_L_ | D21: Laurea Triennale in Ingegneria Industriale L-9 — curriculum Agroindustriale | E21: Laurea Triennale in Ingegneria Industriale L-9 — curriculum Agroindustriale | F21: Laurea in Ingegneria Industriale — curriculum Agroindustriale | G21: Laurea in Ingegneria Industriale — curriculum Agroindustriale | H21: Laurea triennale L-9 | I21: Grado/Bachelor | J21: Programa completo | K21: 2025 | L21: Piano di studi ufficiale A.A. 2025/2026 — última versión oficial recuperada | M21: 3 | N21: Años | O21: Semestres | P21: 6 | Q21: 180 | R21: CFU/ECTS | S21: Italiano | T21: Telemática / actividades según curso | U21: NR | V21: Tirocinio 6 CFU | W21: NR | X21: Sí | Y21: https://www.unicusano.it/ingegneria/piano-di-studi-ingegneria-industriale-curriculum-agroindustriale-l-9 | Z21: 1 | AA21: UNICUSANO | AB21: Laurea L-9 curriculum Agroindustriale | AC21: INTEGRAR CON BANDERA | AD21: APTA PARA BASE MAESTRA | AE21: Versión oficial recuperada 2025/26; conservar inconsistencia de propedeuticità sin inventar equivalencia. | AF21: Sí | AG21: Sí | AH21: No | AI21: No | AJ21: No
A22: CUR_AGRO_HOHENHEIM | B22: HOHENHEIM | C22: HOHENHEIM_B_SC_FOOD_SCIENCE_AND_BIOTECHNOLOGY_LEBENSMIT | D22: B.Sc. Food Science and Biotechnology / Lebensmittelwissenschaft und Biotechnologie | E22: B.Sc. Food Science and Biotechnology / Lebensmittelwissenschaft und Biotechnologie | F22: Bachelor of Science | G22: Bachelor of Science | H22: Bachelor of Science | I22: Grado/Bachelor | J22: Programa completo | K22: 2026 | L22: Programa vigente WS 2026/27 + módulos públicos del catálogo/archivo institucional | M22: 3 | N22: Años | O22: Semestres | P22: 6 | Q22: 180 | R22: ECTS | S22: Alemán | T22: Presencial | U22: Universidad con acreditación de sistema desde 2020 | V22: Prácticas/laboratorios; internship integrable | W22: NR | X22: Sí | Y22: https://dein-studium.uni-hohenheim.de/en/hauptmenue/find-your-degree-program/food-science-and-biotechnology | Z22: 1 | AA22: HOHENHEIM | AB22: B.Sc. completo comparable | AC22: INTEGRAR CON BANDERA | AD22: APTA PARA BASE MAESTRA | AE22: Distinguir módulos vigentes de detalles provenientes del archivo institucional histórico. | AF22: Sí | AG22: Sí | AH22: No | AI22: Condicional | AJ22: Condicional
A23: CUR_AGRO_TUM | B23: TUM | C23: TUM_B_SC_FOOD_TECHNOLOGY_LEBENSMITTELTECHNOLOGIE_CURRIC | D23: B.Sc. Food Technology / Lebensmitteltechnologie | E23: B.Sc. Food Technology / Lebensmitteltechnologie | F23: Bachelor of Science (B.Sc.) | G23: Bachelor of Science (B.Sc.) | H23: Bachelor of Science | I23: Grado/Bachelor | J23: Programa completo | K23: 2026 | L23: Curriculum vigente enlazado por TUM — FPSO 20221, válido para inicio WiSe 23/24; página del programa vigente 2026 | M23: 3 | N23: Años | O23: Semestres | P23: 6 | Q23: 180 | R23: ECTS | S23: Alemán | T23: Full-time / presencial | U23: NR | V23: Industriepraktikum de 6 semanas; 8 ECTS en el curriculum | W23: NR | X23: Sí | Y23: https://www.ls.tum.de/en/ls/studies/courses-and-programs/food-technology-bsc/ | Z23: 1 | AA23: TUM | AB23: B.Sc. completo comparable | AC23: INTEGRAR CON BANDERA | AD23: APTA PARA BASE MAESTRA | AE23: Curriculum actualmente enlazado es válido por cohorte desde WiSe 23/24; no etiquetarlo como PDF emitido en 2026. | AF23: Sí | AG23: Sí | AH23: No | AI23: No | AJ23: No
A24: CUR_AGRO_EPN | B24: EPN | C24: EPN_AGRO_P2020_OFERTA_2026 | D24: Carrera en Agroindustria | E24: Ingeniería Agroindustrial | F24: Ingeniera/o Agroindustrial | G24: Ingeniera/o Agroindustrial | H24: Grado | I24: Grado/Bachelor | J24: Programa completo | K24: 2020 | L24: PÉNSUM 2020 / oferta operacional 2026 | M24: 9 | N24: Períodos académicos | O24: Períodos académicos | P24: 9 | Q24: 135 | R24: Crédito EPN | S24: Español | T24: Presencial | U24: Proceso EUR-ACE / autoevaluación 2025 | V24: Sí | W24: Sí | X24: Sí | Y24: https://www.epn.edu.ec/program-00/ | Z24: 1 | AA24: EPN | AB24: Currículo objetivo comparable | AC24: INTEGRAR COMO TARGET | AD24: TARGET_EPN | AE24: No | AF24: Comparar contra referentes; excluir de denominadores. | AG24: APROBADO CON OBSERVACIONES | AH24: 2026-08-27 | AI24: v1.1

Sheet 04_Curriculo_Institucion
A1: ID_Relacion | B1: ID_Curriculo_Unico | C1: Codigo_Dataset | D1: ID_Universidad_Origen | E1: Universidad | F1: Es_Programa_Conjunto | G1: Cluster_Programa_Conjunto | H1: Rol_Institucion | I1: Archivo_Origen
A2: REL_CUR_AGRO_UPM_UPM | B2: CUR_AGRO_UPM | C2: UPM | D2: UPM | E2: Universidad Politécnica de Madrid (ETSIAAB) | F2: No | H2: Institución única | I2: UPM_Extractor_v1_1_Agro_Grado_Ingenieria_Alimentaria_20IA_2026_27_AUDITADO.xlsx
A3: REL_CUR_AGRO_USAL_USAL | B3: CUR_AGRO_USAL | C3: USAL | D3: USAL | E3: Universidad de Salamanca | F3: No | H3: Institución única | I3: USAL_Agro_Grado_Ingenieria_Agroalimentaria_Plan_2026_AUDITADO.xlsx
A4: REL_CUR_AGRO_USC_USC | B4: CUR_AGRO_USC | C4: USC | D4: USC | E4: Universidade de Santiago de Compostela (EPS Lugo) | F4: No | H4: Institución única | I4: USC_Agro_Grao_Enxenaria_Agricola_Agroalimentaria_IAA_AUDITADO.xlsx
A5: REL_CUR_AGRO_UPC_UPC | B5: CUR_AGRO_UPC | C5: UPC | D5: UPC | E5: Universitat Politècnica de Catalunya (EEABB) | F5: No | H5: Institución única | I5: UPC_Agro_Grau_Enginyeria_Alimentaria_2026_27_AUDITADO.xlsx
A6: REL_CUR_AGRO_SEVILLA_SEVILLA | B6: CUR_AGRO_SEVILLA | C6: SEVILLA | D6: US | E6: Universidad de Sevilla | F6: No | H6: Institución única | I6: US_Agro_Grado_Ingenieria_Agricola_Explotaciones_Agropecuarias_AUDITADO.xlsx
A7: REL_CUR_AGRO_UCO_UCO | B7: CUR_AGRO_UCO | C7: UCO | D7: UCO | E7: Universidad de Córdoba | F7: No | H7: Institución única | I7: UCO_Agro_Grado_Ingenieria_Agroalimentaria_Mencion_Ingenieria_Alimentaria_2026_27_AUDITADO.xlsx
A8: REL_CUR_AGRO_UMH_UMH | B8: CUR_AGRO_UMH | C8: UMH | D8: UMH | E8: Universidad Miguel Hernández | F8: No | H8: Institución única | I8: UMH_Agro_Grado_Ingenieria_Agroalimentaria_Agroambiental_IAA_2026_27_AUDITADO.xlsx
A9: REL_CUR_AGRO_ENSAIA_ENSAIA | B9: CUR_AGRO_ENSAIA | C9: ENSAIA | D9: ENSAIA | E9: ENSAIA – Université de Lorraine | F9: No | H9: Institución única | I9: ENSAIA_Agro_Ingenieur_Industries_Alimentaires_S5_S10_AUDITADO.xlsx
A10: REL_CUR_AGRO_IARA_IARA | B10: CUR_AGRO_IARA | C10: IARA | D10: IARA | E10: L'Institut Agro Rennes-Angers | F10: No | H10: Institución única | I10: Institut_Agro_Rennes_Angers_Agro_Ingenieur_Alimentation_AUDITADO.xlsx
A11: REL_CUR_AGRO_ONIRIS_ONIRIS | B11: CUR_AGRO_ONIRIS | C11: ONIRIS | D11: ONIRIS | E11: ONIRIS Nantes | F11: No | H11: Institución única | I11: ONIRIS_Agro_Ingenieur_Agroalimentaire_ING2_AUDITADO.xlsx
A12: REL_CUR_AGRO_AGROPARISTECH_AGROPARISTECH | B12: CUR_AGRO_AGROPARISTECH | C12: AGROPARISTECH | D12: AGROPARISTECH | E12: AgroParisTech | F12: No | H12: Institución única | I12: AgroParisTech_Agro_Domaine2_Parcours_Ingenierie_Aliments_AUDITADO.xlsx
A13: REL_CUR_AGRO_IAD_IAD | B13: CUR_AGRO_IAD | C13: IAD | D13: IAD | E13: L'Institut Agro Dijon | F13: No | H13: Institución única | I13: Institut_Agro_Dijon_Agro_Ingenieur_Alimentation_AUDITADO.xlsx
... A15: REL_CUR_AGRO_PURPAN_PURPAN | B15: CUR_AGRO_PURPAN | C15: PURPAN | D15: PURPAN | E15: École d'Ingénieurs de PURPAN | F15: No | H15: Institución única | I15: PURPAN_Agro_Cursus_Ingenieur_2026_27_AUDITADO.xlsx
A16: REL_CUR_AGRO_PT_EA_JOINT_IPB_IPL_IPVC_IPB | B16: CUR_AGRO_PT_EA_JOINT_IPB_IPL_IPVC | C16: IPB | D16: IPB | E16: Instituto Politécnico de Bragança | F16: Sí | G16: JOINT_EA_PT | H16: Principal/cotitular | I16: IPB_ESA_Agro_Licenciatura_Engenharia_Alimentar_Conjunta_AUDITADO.xlsx
A17: REL_CUR_AGRO_PT_EA_JOINT_IPB_IPL_IPVC_IPLEIRIA | B17: CUR_AGRO_PT_EA_JOINT_IPB_IPL_IPVC | C17: IPLEIRIA | D17: IPLEIRIA | E17: Politécnico de Leiria | F17: Sí | G17: JOINT_EA_PT | H17: Principal/cotitular | I17: IPLeiria_Agro_Licenciatura_Engenharia_Alimentar_Conjunta_AUDITADO.xlsx
A18: REL_CUR_AGRO_PT_EA_JOINT_IPB_IPL_IPVC_IPVC | B18: CUR_AGRO_PT_EA_JOINT_IPB_IPL_IPVC | C18: IPVC | D18: IPVC | E18: Instituto Politécnico de Viana do Castelo | F18: Sí | G18: JOINT_EA_PT | H18: Principal/cotitular | I18: IPVC_Agro_Licenciatura_Engenharia_Alimentar_Conjunta_AUDITADO.xlsx
A19: REL_CUR_AGRO_ISA_ISA | B19: CUR_AGRO_ISA | C19: ISA | D19: ISA_ULISBOA | E19: Instituto Superior de Agronomia – Universidade de Lisboa | F19: No | H19: Institución única | I19: ISA_Universidade_Lisboa_Agro_Licenciatura_Engenharia_Alimentar_2026_27_AUDITADO.xlsx
A20: REL_CUR_AGRO_ESAV_ESAV | B20: CUR_AGRO_ESAV | C20: ESAV | D20: ESAV_IPV | E20: Instituto Politécnico de Viseu – ESAV | F20: No | H20: Institución única | I20: IPV_ESAV_Agro_Licenciatura_Engenharia_Alimentar_2026_27_AUDITADO.xlsx
A21: REL_CUR_AGRO_UNIBO_UNIBO | B21: CUR_AGRO_UNIBO | C21: UNIBO | D21: UNIBO | E21: Università di Bologna | F21: No | H21: Institución única | I21: Universita_Bologna_Agro_Tecnologie_Alimentari_2026_27_AUDITADO.xlsx
A22: REL_CUR_AGRO_UNIFG_UNIFG | B22: CUR_AGRO_UNIFG | C22: UNIFG | D22: UNIFG | E22: Università degli Studi di Foggia | F22: No | H22: Institución única | I22: Universita_Foggia_Agro_Scienze_Tecnologie_Alimentari_2026_27_AUDITADO.xlsx
A23: REL_CUR_AGRO_UNICUSANO_UNICUSANO | B23: CUR_AGRO_UNICUSANO | C23: UNICUSANO | D23: UNICUSANO | E23: Università Niccolò Cusano | F23: No | H23: Institución única | I23: Unicusano_Agro_Ingegneria_Industriale_Curriculum_Agroindustriale_2025_26_AUDITADO.xlsx
A24: REL_CUR_AGRO_HOHENHEIM_HOHENHEIM | B24: CUR_AGRO_HOHENHEIM | C24: HOHENHEIM | D24: HOHENHEIM | E24: Universität Hohenheim | F24: No | H24: Institución única | I24: Universitat_Hohenheim_Agro_Food_Science_Biotechnology_2026_27_AUDITADO.xlsx
A25: REL_CUR_AGRO_TUM_TUM | B25: CUR_AGRO_TUM | C25: TUM | D25: TUM | E25: Technische Universität München | F25: No | H25: Institución única | I25: TUM_Agro_BSc_Food_Technology_2026_AUDITADO.xlsx
A26: REL_CUR_AGRO_EPN_EPN | B26: CUR_AGRO_EPN | C26: EPN | D26: EPN | E26: Escuela Politécnica Nacional | F26: No | H26: Institución única / TARGET | I26: EPN_AGRO_Dataset_Comparativo_Integrable_v1_0.xlsx

Sheet 05_Programas_Origen
A1: Codigo_Dataset | B1: ID_Curriculo_Unico | C1: Nivel_Marco_Comparativo | D1: Alcance_Dataset | E1: Decision_Integracion | F1: ID_Programa | G1: ID_Universidad | H1: Nombre_programa_original | I1: Nombre_programa_espanol | J1: Titulo_otorgado_original | K1: Titulo_otorgado_espanol | L1: Nivel_programa | M1: Anio_malla | N1: Version_malla | O1: Duracion_valor | P1: Duracion_unidad | Q1: Sistema_periodos_original | R1: Numero_total_periodos | S1: Creditos_totales | T1: Sistema_creditos | U1: Idioma | V1: Modalidad | W1: Acreditacion_reportada | X1: Practica_industrial_reportada | Y1: Vinculacion_reportada | Z1: Tesis_reportada | AA1: Proyecto_final_reportado | AB1: URL_programa | AC1: ID_Fuente_principal | AD1: Estado_extraccion | AE1: Observaciones
A2: UPM | B2: CUR_AGRO_UPM | C2: Grado/Bachelor | D2: Programa completo | E2: INTEGRAR | F2: UPM_20IA_2026_27 | G2: UPM | H2: Grado en Ingeniería Alimentaria | I2: Grado en Ingeniería Alimentaria | J2: Graduado/a en Ingeniería Alimentaria por la Universidad Politécnica de Madrid | K2: Graduado/a en Ingeniería Alimentaria por la Universidad Politécnica de Madrid | L2: Grado | M2: 2026 | N2: Plan 20IA — curso 2026/27 | O2: 4 | P2: Años | Q2: Semestres | R2: 8 | S2: 240 | T2: ECTS | U2: Español; determinadas materias pueden impartirse en inglés | V2: Presencial | W2: ABET; EUR-ACE | X2: Sí | Y2: NR | Z2: NR | AA2: Sí | AB2: https://www.etsiaab.upm.es/Docencia/Grados/IngAlimentaria | AC2: UPM_20IA_2026_27_F001 | AD2: Revisado | AE2: Prácticas académicas externas curriculares pueden reconocerse dentro de los 14 ECTS optativos, con máximo 6 ECTS por prácticas.
A3: USAL | B3: CUR_AGRO_USAL | C3: Grado/Bachelor | D3: Programa completo | E3: INTEGRAR | F3: USAL_GRADO_EN_INGENIER_A_AGROALIMENTARIA_P | G3: USAL | H3: Grado en Ingeniería Agroalimentaria — Plan 2026 | I3: Grado en Ingeniería Agroalimentaria — Plan 2026 | J3: Graduado/a en Ingeniería Agroalimentaria | K3: Graduado/a en Ingeniería Agroalimentaria | L3: Grado | M3: 2026 | N3: Plan 2026 / curso 2026-27 | O3: 4 | P3: Años | Q3: Semestres | R3: 8 | S3: 240 | T3: ECTS | U3: Español | V3: Presencial | W3: Habilitante para la profesión regulada de Ingeniero Técnico Agrícola | X3: NR | Y3: NR | Z3: NR | AA3: Sí | AB3: https://usal.es/grado-en-ingenieria-agroalimentaria | AC3: USAL_GRADO_EN_INGENIER_A_AGROALIMENTARIA_P_F001 | AD3: Revisado | AE3: Comparabilidad con Agroindustria EPN: Muy alta. Título de ingeniería agroalimentaria de grado con formación explícita en tecnología de alimentos, procesos, calidad, instalaciones, industrias alimentarias, residuos y gestión.
